<?xml version="1.0" ?>
<robot name="urdf-model" xmlns:xacro="http://www.ros.org/wiki/xacro">

<xacro:include filename="$(find urdf-model_description)/urdf/materials.xacro" />
<xacro:include filename="$(find urdf-model_description)/urdf/urdf-model.trans" />
<xacro:include filename="$(find urdf-model_description)/urdf/urdf-model.gazebo" />
<link name="base_link">
  <inertial>
    <origin rpy="0 0 0" xyz="-0.0275061013551108 -0.004341483810504465 0.09680298938914361"/>
    <mass value="2.1080129630892235"/>
    <inertia ixx="0.031032" ixy="-0.000398" ixz="0.002171" iyy="0.040587" iyz="0.000128" izz="0.066435"/>
  </inertial>
  <visual>
    <origin rpy="0 0 0" xyz="0 0 0"/>
    <geometry>
      <mesh filename="package://urdf-model_description/meshes/base_link.stl" scale="0.001 0.001 0.001"/>
    </geometry>
    <material name="silver"/>
  </visual>
  <collision>
    <origin rpy="0 0 0" xyz="0 0 0"/>
    <geometry>
      <mesh filename="package://urdf-model_description/meshes/base_link.stl" scale="0.001 0.001 0.001"/>
    </geometry>
  </collision>
</link>

<link name="left_wheel_1">
  <inertial>
    <origin rpy="0 0 0" xyz="1.004166337169966e-15 -0.007999999999999813 3.2612801348363973e-16"/>
    <mass value="0.10107848168254108"/>
    <inertia ixx="5.7e-05" ixy="0.0" ixz="0.0" iyy="0.000109" iyz="0.0" izz="5.7e-05"/>
  </inertial>
  <visual>
    <origin rpy="0 0 0" xyz="-0.0 0.2115 -0.0465"/>
    <geometry>
      <mesh filename="package://urdf-model_description/meshes/left_wheel_1.stl" scale="0.001 0.001 0.001"/>
    </geometry>
    <material name="silver"/>
  </visual>
  <collision>
    <origin rpy="0 0 0" xyz="-0.0 0.2115 -0.0465"/>
    <geometry>
      <mesh filename="package://urdf-model_description/meshes/left_wheel_1.stl" scale="0.001 0.001 0.001"/>
    </geometry>
  </collision>
</link>

<link name="right_wheel_1">
  <inertial>
    <origin rpy="0 0 0" xyz="-2.1077518583023611e-07 0.00800000000000023 2.983724378680108e-16"/>
    <mass value="0.10107848168254113"/>
    <inertia ixx="5.7e-05" ixy="0.0" ixz="0.0" iyy="0.000109" iyz="0.0" izz="5.7e-05"/>
  </inertial>
  <visual>
    <origin rpy="0 0 0" xyz="3e-05 -0.1925 -0.0465"/>
    <geometry>
      <mesh filename="package://urdf-model_description/meshes/right_wheel_1.stl" scale="0.001 0.001 0.001"/>
    </geometry>
    <material name="silver"/>
  </visual>
  <collision>
    <origin rpy="0 0 0" xyz="3e-05 -0.1925 -0.0465"/>
    <geometry>
      <mesh filename="package://urdf-model_description/meshes/right_wheel_1.stl" scale="0.001 0.001 0.001"/>
    </geometry>
  </collision>
</link>

<link name="lidar_1">
  <inertial>
    <origin rpy="0 0 0" xyz="4.9028732576617e-07 6.591949208711867e-17 0.012500000000000039"/>
    <mass value="0.10406525665016184"/>
    <inertia ixx="3.8e-05" ixy="-0.0" ixz="-0.0" iyy="3.8e-05" iyz="0.0" izz="6.5e-05"/>
  </inertial>
  <visual>
    <origin rpy="0 0 0" xyz="0.125032 0.01 -0.1595"/>
    <geometry>
      <mesh filename="package://urdf-model_description/meshes/lidar_1.stl" scale="0.001 0.001 0.001"/>
    </geometry>
    <material name="silver"/>
  </visual>
  <collision>
    <origin rpy="0 0 0" xyz="0.125032 0.01 -0.1595"/>
    <geometry>
      <mesh filename="package://urdf-model_description/meshes/lidar_1.stl" scale="0.001 0.001 0.001"/>
    </geometry>
  </collision>
</link>

<joint name="Rev7" type="continuous">
  <origin rpy="0 0 0" xyz="0.0 -0.2115 0.0465"/>
  <parent link="base_link"/>
  <child link="left_wheel_1"/>
  <axis xyz="0.0 1.0 0.0"/>
</joint>

<joint name="Rev8" type="continuous">
  <origin rpy="0 0 0" xyz="-3e-05 0.1925 0.0465"/>
  <parent link="base_link"/>
  <child link="right_wheel_1"/>
  <axis xyz="-0.0 1.0 -0.0"/>
</joint>

<joint name="Rigid9" type="fixed">
  <origin rpy="0 0 0" xyz="-0.125032 -0.01 0.1595"/>
  <parent link="base_link"/>
  <child link="lidar_1"/>
</joint>

</robot>
